Workbook
Name \_A: #N/A
Name \0: #REF!
Name \0: #REF!
Name \1: #REF!
Name \1: #REF!
Name \2: #REF!
Name \2: #REF!
Name \3: #REF!
Name \4: #REF!
Name \5: #REF!
Name \6: #REF!
Name \A: #REF!
Name \A: #REF!
Name \APR: #REF!
Name \AUG: #REF!
Name \B: #REF!
Name \B: #REF!
Name \BCYTD: #REF!
Name \BRYTD: #REF!
Name \BSYTD: #REF!
Name \BTWO: #REF!
Name \BUYTD: #REF!
Name \C: #REF!
Name \c: #REF!
Name \CTWO: #REF!
Name \D: #REF!
Name \D: #REF!
Name \DEC: #REF!
Name \DTWO: #REF!
Name \E: #REF!
Name \E: #REF!
Name \F: #REF!
Name \F: #REF!
Name \FEB: #REF!
Name \G: #REF!
Name \g: #REF!
Name \H: #REF!
Name \I: #REF!
Name \I: #REF!
Name \J: #REF!
Name \JAN: #REF!
Name \K: #REF!
Name \L: #REF!
Name \M: #REF!
Name \MAR: #REF!
Name \MAY: #REF!
Name \N: #REF!
Name \NOV: #REF!
Name \O: #REF!
Name \O: #REF!
Name \OCT: #REF!
Name \p: #N/A
Name \p: #REF!
Name \Q: #REF!
Name \Q: #REF!
Name \R: #REF!
Name \r: #REF!
Name \S: #REF!
Name \S: #REF!
Name \SEP: #REF!

Sheet Parameter
C1: Budget 2027
C2: ASSUMPTION
B4: No | C4: Item Budget | D4: Parameter | E4: PIC
B5: 1 | C5: Inflation Rate | D5: 3.5%
B6: 2 | C6: Target Marketing Revenue | D6: Target Marketing Revenue that will be achieved for year 2027 | E6: Sales Division
B7: 3 | C7: Sales Cost | D7: Base on achievement Target Marketing Revenue | E7: Sales Division
B8: =B7+1 -> 4 | C8: Program Sales | D8: Base on Approved Program Sales | E8: Sales Division
B9: =B8+1 -> 5 | C9: Marketing Advertising & Promotion | D9: Marketing division must list the detail of planning activity during the next year, and the activity must be inline with the Target Marketing Revenue | E9: Marketing Division
B10: =B9+1 -> 6 | C10: Development Cost | D10: Development cost planning that will be allocated in 2027, inline with development schedule and vendor contract agreement | E10: Project Division
B11: 7 | C11: Employee Expenses
C12: MPP | D12: Base on approved MPP | E12: HC Divison
C13: MPP Cost | D13: Base on approved MPP | E13: Payroll Division
B14: 8 | C14: General & Administration Expenses | D14: Base on actual need | E14: ALL Division
B15: 9 | C15: Others Expenses | D15: Base on actual need | E15: ALL Division
B16: 10 | C16: Tax Expenses | D16: Base on Tax expense | E16: ALL Division
B17: 11 | C17: Corporate Event & Exhibition | D17: The Division must list the detail of planning activity during the next year, and the activity must be inline with the Corporate/Management Strategic | E17: Corporate Division
B18: =B17+1 -> 12 | C18: Finance Expenses | D18: Base on agreed Interest | E18: FA Division
B19: =B18+1 -> 13 | C19: Fixed Asset | D19: Base on actual need | E19: ALL Division
C20: Laptop/PC | D20: Specification base on IT Policy | E20: ALL Division
C21: Printer | D21: Specification base on IT Policy | E21: ALL Division
C22: Monitor PC | D22: Specification base on IT Policy | E22: ALL Division
C23: Projector Presentation | D23: Specification base on IT Policy | E23: ALL Division
C24: Others IT Equipment | D24: Specification base on IT Policy | E24: ALL Division
C25: Work Desk & Chair | D25: Specification base on GA Policy | E25: ALL Division
C26: Company/Operational Vehicle | D26: Specification base on GA Policy | E26: ALL Division
C27: Others Fixed Asset | D27: Specification base on GA Policy | E27: ALL Division

Sheet Fixed Asset
A2: Budget CAPEX (Fixed Asset)
A3: Comp Name
A4: Project
A5: Budget Year | B5: 2022
A7: BUDGET CAPEX REQUEST FORM
A9: No | B9: Employee Name | C9: Divison / Dept | D9: Fixed Asset Category | E9: Item Goods Description | F9: Periode | G9: Qty | J9: UoM | K9: Price / unit | L9: Curr | M9: Total Value Local Currency | N9: Justification | O9: Reason | P9: Competent Division | Q9: Procurement
G10: New | H10: Replace | I10: Total | P10: Review Result | Q10: Review Result
B11: Lembar isian Budget Capex | T11: Budget Capex Summary
A12: 1 | I12: =SUM(G12:H12) -> 0 | J12: set | L12: IDR | M12: =I12*K12 -> 0 | U12: 44197 | V12: 44228 | W12: 44256 | X12: 44287 | Y12: 44317 | Z12: 44348 | AA12: 44378 | AB12: 44409 | AC12: 44440 | AD12: 44470 | AE12: 44501 | AF12: 44531 | AG12: Total
A13: 2 | B13: Rudi | C13: Sales Marketing | D13: IT Hardware & Software | E13: Laptop for Vacant Inhouse Sales | F13: 44621 | G13: 1 | H13: 0 | I13: =SUM(G13:H13) -> 1 | J13: Set | K13: 8000000 | L13: IDR | M13: =I13*K13 -> 8000000 | N13: Must To Have | T13: Bangunan | U13: =SUMIFS($M:$M,$F:$F,U$12,$D:$D,$T13) -> 0 | V13: =SUMIFS($M:$M,$F:$F,V$12,$D:$D,$T13) -> 0 | W13: =SUMIFS($M:$M,$F:$F,W$12,$D:$D,$T13) -> 0 | X13: =SUMIFS($M:$M,$F:$F,X$12,$D:$D,$T13) -> 0 | Y13: =SUMIFS($M:$M,$F:$F,Y$12,$D:$D,$T13) -> 0 | Z13: =SUMIFS($M:$M,$F:$F,Z$12,$D:$D,$T13) -> 0 | AA13: =SUMIFS($M:$M,$F:$F,AA$12,$D:$D,$T13) -> 0 | AB13: =SUMIFS($M:$M,$F:$F,AB$12,$D:$D,$T13) -> 0 | ... AF13: =SUMIFS($M:$M,$F:$F,AF$12,$D:$D,$T13) -> 0 | AG13: =SUM(U13:AF13) -> 0
A14: 3 | I14: =SUM(G14:H14) -> 0 | L14: IDR | M14: =I14*K14 -> 0 | T14: Kendaraan Operasional | U14: =SUMIFS($M:$M,$F:$F,U$12,$D:$D,$T14) -> 0 | V14: =SUMIFS($M:$M,$F:$F,V$12,$D:$D,$T14) -> 0 | W14: =SUMIFS($M:$M,$F:$F,W$12,$D:$D,$T14) -> 0 | X14: =SUMIFS($M:$M,$F:$F,X$12,$D:$D,$T14) -> 0 | Y14: =SUMIFS($M:$M,$F:$F,Y$12,$D:$D,$T14) -> 0 | Z14: =SUMIFS($M:$M,$F:$F,Z$12,$D:$D,$T14) -> 0 | AA14: =SUMIFS($M:$M,$F:$F,AA$12,$D:$D,$T14) -> 0 | AB14: =SUMIFS($M:$M,$F:$F,AB$12,$D:$D,$T14) -> 0 | ... AF14: =SUMIFS($M:$M,$F:$F,AF$12,$D:$D,$T14) -> 0 | AG14: =SUM(U14:AF14) -> 0
A15: 4 | I15: =SUM(G15:H15) -> 0 | L15: IDR | M15: =I15*K15 -> 0 | T15: Peralatan Kantor | U15: =SUMIFS($M:$M,$F:$F,U$12,$D:$D,$T15) -> 0 | V15: =SUMIFS($M:$M,$F:$F,V$12,$D:$D,$T15) -> 0 | W15: =SUMIFS($M:$M,$F:$F,W$12,$D:$D,$T15) -> 0 | X15: =SUMIFS($M:$M,$F:$F,X$12,$D:$D,$T15) -> 0 | Y15: =SUMIFS($M:$M,$F:$F,Y$12,$D:$D,$T15) -> 0 | Z15: =SUMIFS($M:$M,$F:$F,Z$12,$D:$D,$T15) -> 0 | AA15: =SUMIFS($M:$M,$F:$F,AA$12,$D:$D,$T15) -> 0 | AB15: =SUMIFS($M:$M,$F:$F,AB$12,$D:$D,$T15) -> 0 | ... AF15: =SUMIFS($M:$M,$F:$F,AF$12,$D:$D,$T15) -> 0 | AG15: =SUM(U15:AF15) -> 0
A16: 5 | I16: =SUM(G16:H16) -> 0 | L16: IDR | M16: =I16*K16 -> 0 | T16: Furnitur dan Perlengkapan Kantor | U16: =SUMIFS($M:$M,$F:$F,U$12,$D:$D,$T16) -> 0 | V16: =SUMIFS($M:$M,$F:$F,V$12,$D:$D,$T16) -> 0 | W16: =SUMIFS($M:$M,$F:$F,W$12,$D:$D,$T16) -> 0 | X16: =SUMIFS($M:$M,$F:$F,X$12,$D:$D,$T16) -> 0 | Y16: =SUMIFS($M:$M,$F:$F,Y$12,$D:$D,$T16) -> 0 | Z16: =SUMIFS($M:$M,$F:$F,Z$12,$D:$D,$T16) -> 0 | AA16: =SUMIFS($M:$M,$F:$F,AA$12,$D:$D,$T16) -> 0 | AB16: =SUMIFS($M:$M,$F:$F,AB$12,$D:$D,$T16) -> 0 | ... AF16: =SUMIFS($M:$M,$F:$F,AF$12,$D:$D,$T16) -> 0 | AG16: =SUM(U16:AF16) -> 0
A17: 6 | I17: =SUM(G17:H17) -> 0 | L17: IDR | M17: =I17*K17 -> 0 | T17: IT Hardware & Software | U17: =SUMIFS($M:$M,$F:$F,U$12,$D:$D,$T17) -> 0 | V17: =SUMIFS($M:$M,$F:$F,V$12,$D:$D,$T17) -> 0 | W17: =SUMIFS($M:$M,$F:$F,W$12,$D:$D,$T17) -> 0 | X17: =SUMIFS($M:$M,$F:$F,X$12,$D:$D,$T17) -> 0 | Y17: =SUMIFS($M:$M,$F:$F,Y$12,$D:$D,$T17) -> 0 | Z17: =SUMIFS($M:$M,$F:$F,Z$12,$D:$D,$T17) -> 0 | AA17: =SUMIFS($M:$M,$F:$F,AA$12,$D:$D,$T17) -> 0 | AB17: =SUMIFS($M:$M,$F:$F,AB$12,$D:$D,$T17) -> 0 | ... AF17: =SUMIFS($M:$M,$F:$F,AF$12,$D:$D,$T17) -> 0 | AG17: =SUM(U17:AF17) -> 0
A18: 7 | I18: =SUM(G18:H18) -> 0 | L18: IDR | M18: =I18*K18 -> 0 | T18: Peralatan Lainnya | U18: =SUMIFS($M:$M,$F:$F,U$12,$D:$D,$T18) -> 0 | V18: =SUMIFS($M:$M,$F:$F,V$12,$D:$D,$T18) -> 0 | W18: =SUMIFS($M:$M,$F:$F,W$12,$D:$D,$T18) -> 0 | X18: =SUMIFS($M:$M,$F:$F,X$12,$D:$D,$T18) -> 0 | Y18: =SUMIFS($M:$M,$F:$F,Y$12,$D:$D,$T18) -> 0 | Z18: =SUMIFS($M:$M,$F:$F,Z$12,$D:$D,$T18) -> 0 | AA18: =SUMIFS($M:$M,$F:$F,AA$12,$D:$D,$T18) -> 0 | AB18: =SUMIFS($M:$M,$F:$F,AB$12,$D:$D,$T18) -> 0 | ... AF18: =SUMIFS($M:$M,$F:$F,AF$12,$D:$D,$T18) -> 0 | AG18: =SUM(U18:AF18) -> 0
A19: 8 | I19: =SUM(G19:H19) -> 0 | L19: IDR | M19: =I19*K19 -> 0 | U19: =SUM(U13:U18) -> 0 | V19: =SUM(V13:V18) -> 0 | W19: =SUM(W13:W18) -> 0 | X19: =SUM(X13:X18) -> 0 | Y19: =SUM(Y13:Y18) -> 0 | Z19: =SUM(Z13:Z18) -> 0 | AA19: =SUM(AA13:AA18) -> 0 | AB19: =SUM(AB13:AB18) -> 0 | ... AF19: =SUM(AF13:AF18) -> 0 | AG19: =SUM(U19:AF19) -> 0
A20: 9 | I20: =SUM(G20:H20) -> 0 | L20: IDR | M20: =I20*K20 -> 0
A21: 10 | I21: =SUM(G21:H21) -> 0 | L21: IDR | M21: =I21*K21 -> 0
A22: 11 | I22: =SUM(G22:H22) -> 0 | L22: IDR | M22: =I22*K22 -> 0
A23: 12 | I23: =SUM(G23:H23) -> 0 | L23: IDR | M23: =I23*K23 -> 0
A24: 13 | I24: =SUM(G24:H24) -> 0 | L24: IDR | M24: =I24*K24 -> 0 | T24: Depreciation of Capex
A25: 14 | I25: =SUM(G25:H25) -> 0 | L25: IDR | M25: =I25*K25 -> 0 | W25: =U12 -> 44197 | X25: =V12 -> 44228 | Y25: =W12 -> 44256 | Z25: =X12 -> 44287 | AA25: =Y12 -> 44317 | AB25: =Z12 -> 44348 | AC25: =AA12 -> 44378 | AD25: =AB12 -> 44409 | ... AI25: =AG12 -> Total
A26: 15 | I26: =SUM(G26:H26) -> 0 | L26: IDR | M26: =I26*K26 -> 0 | T26: Biaya Penyusutan Bangunan | U26: Bangunan | AI26: =SUM(W26:AH26) -> 0
A27: 16 | I27: =SUM(G27:H27) -> 0 | L27: IDR | M27: =I27*K27 -> 0 | T27: Biaya Penyusutan Kendaraan Kantor | U27: Kendaraan Operasional | AI27: =SUM(W27:AH27) -> 0
A28: 17 | I28: =SUM(G28:H28) -> 0 | L28: IDR | M28: =I28*K28 -> 0 | T28: Biaya Penyusutan Inventaris Kantor | U28: Peralatan Kantor | AI28: =SUM(W28:AH28) -> 0
A29: 18 | I29: =SUM(G29:H29) -> 0 | L29: IDR | M29: =I29*K29 -> 0 | T29: Biaya Penyusutan Inventaris Kantor | U29: Furnitur dan Perlengkapan Kantor
A30: 19 | I30: =SUM(G30:H30) -> 0 | L30: IDR | M30: =I30*K30 -> 0 | T30: Biaya Penyusutan Inventaris Kantor | U30: IT Hardware & Software
A31: 20 | I31: =SUM(G31:H31) -> 0 | L31: IDR | M31: =I31*K31 -> 0 | T31: Biaya Penyusutan Inventaris Kantor | U31: Peralatan Lainnya
E32: TOTAL | L32: IDR | M32: =SUM(M12:M31) -> 8000000
B34: Create by, | D34: Competent Division, | I34: Review by, | O34: Approved by,
B38: Name : ____________________ | D38: Name : ____________________ | E38: Name : ____________________ | I38: Name : ____________________ | O38: Name : __________________
B39: ="Division : "&" "&B5 -> Division : 2022 | D39: Comp Div Name : ____________ | E39: Comp Div Name : ____________ | I39: Head of FA | O39: Director
B40: =B3 -> 0 | D40: =B3 -> 0 | E40: =B3 -> 0 | I40: =B3 -> 0 | O40: =B3 -> 0

Sheet Attachment1
A1: KEBIJAKAN No : PM/TRIN/HC/01
A60: Business Trip
A61: Gol / Jabatan | B61: Hotels | C61: Uang Saku & Uang Makan Lum Sum | E61: Transport
A62: Commissary
A63: BOD / BOC | B63: 1650000 | C63: 500000
A64: General Manager | B64: 900000 | C64: 400000
A65: Manager | B65: 750000 | C65: 300000
A66: Supervisor | B66: 600000 | C66: 250000
A67: Staff | B67: 500000 | C67: 150000
A68: Contract

Sheet SUM Actual vs Budget
A1: SUMMARY BUDGET
A2: ENTITAS: | B2: PT Perintis Triniti Properti Tbk
A3: PROJECT | B3: Lampung-Holdwell Business Park
A4: BUDGET YEARS | B4: BUDGET 2023
A5: MONTH: | B5: YTD SEP
B7: Description | C7: 2020 | D7: BUDGET | E7: ACTUAL | F7: Budget Realization | H7: BUDGET | I7: Budget 2022 vs Budget 2023 | J7: Budget 2023 vs Actual 2022 | L7: BUDGET | N7: BUDGET
C8: ACTUAL | D8: 2022 | E8: 2022 | F8: 2022 | H8: 2023 | I8: B2022 vs B2023 | J8: B2023 vs A2022 | L8: 2024 | N8: 2025
C9: YTD DEC | D9: YTD DEC | E9: YTD DEC | F9: =E9 -> YTD DEC | H9: YTD DEC | I9: YTD DEC | J9: YTD DEC | L9: YTD DEC | N9: YTD DEC
B11: SALES
A13: 1 | B13: in SQM
A14: 2 | B14: ='Target Marketing Revenue'!B54 -> 0 | C14: 0 | F14: =IFERROR(E14/D14,0) -> 0 | H14: =HLOOKUP(H$9,'Target Marketing Revenue'!$E$53:$P$61,$A14,FALSE) -> 0 | I14: =IFERROR(H14/D14-1,0) -> 0 | J14: =IFERROR(H14/E14-1,0) -> 0
A15: 3 | B15: ='Target Marketing Revenue'!B55 -> 0 | F15: =IFERROR(E15/D15,0) -> 0 | H15: =HLOOKUP(H$9,'Target Marketing Revenue'!$E$53:$P$61,$A15,FALSE) -> 0 | I15: =IFERROR(H15/D15-1,0) -> 0 | J15: =IFERROR(H15/E15-1,0) -> 0
A16: 4 | B16: ='Target Marketing Revenue'!B56 -> 0 | F16: =IFERROR(E16/D16,0) -> 0 | H16: =HLOOKUP(H$9,'Target Marketing Revenue'!$E$53:$P$61,$A16,FALSE) -> 0 | I16: =IFERROR(H16/D16-1,0) -> 0 | J16: =IFERROR(H16/E16-1,0) -> 0
A17: 5 | B17: ='Target Marketing Revenue'!B57 -> 0 | C17: 0 | F17: =IFERROR(E17/D17,0) -> 0 | H17: =HLOOKUP(H$9,'Target Marketing Revenue'!$E$53:$P$61,$A17,FALSE) -> 0 | I17: =IFERROR(H17/D17-1,0) -> 0 | J17: =IFERROR(H17/E17-1,0) -> 0
A18: 6 | B18: ='Target Marketing Revenue'!B58 -> 0 | C18: 0 | F18: =IFERROR(E18/D18,0) -> 0 | H18: =HLOOKUP(H$9,'Target Marketing Revenue'!$E$53:$P$61,$A18,FALSE) -> 0 | I18: =IFERROR(H18/D18-1,0) -> 0 | J18: =IFERROR(H18/E18-1,0) -> 0
C19: 0
B20: ="TOTAL"&" "&B11&" "&B13 -> TOTAL SALES in SQM | C20: =SUM(C14:C19) -> 0 | D20: =SUM(D14:D19) -> 0 | E20: =SUM(E14:E19) -> 0 | F20: =IFERROR(E20/D20,0) -> 0 | H20: =SUM(H14:H19) -> 0 | I20: =IFERROR(H20/D20-1,0) -> 0 | J20: =IFERROR(H20/E20-1,0) -> 0 | L20: =SUM(L14:L19) -> 0 | N20: =SUM(N14:N19) -> 0
A22: 1 | B22: MARKETING REVENUE (in Rp Bio)
A23: 2 | B23: ='Target Marketing Revenue'!B64 -> 0 | C23: 0 | F23: =IFERROR(E23/D23,0) -> 0 | H23: =HLOOKUP(H$9,'Target Marketing Revenue'!$E$63:$P$71,$A23,FALSE) -> 0 | I23: =IFERROR(H23/D23-1,0) -> 0 | J23: =IFERROR(H23/E23-1,0) -> 0
A24: 3 | B24: ='Target Marketing Revenue'!B65 -> 0 | F24: =IFERROR(E24/D24,0) -> 0 | H24: =HLOOKUP(H$9,'Target Marketing Revenue'!$E$63:$P$71,$A24,FALSE) -> 0 | I24: =IFERROR(H24/D24-1,0) -> 0 | J24: =IFERROR(H24/E24-1,0) -> 0
A25: 4 | B25: ='Target Marketing Revenue'!B66 -> 0 | F25: =IFERROR(E25/D25,0) -> 0 | H25: =HLOOKUP(H$9,'Target Marketing Revenue'!$E$63:$P$71,$A25,FALSE) -> 0 | I25: =IFERROR(H25/D25-1,0) -> 0 | J25: =IFERROR(H25/E25-1,0) -> 0
A26: 5 | B26: ='Target Marketing Revenue'!B67 -> 0 | C26: 0 | F26: =IFERROR(E26/D26,0) -> 0 | H26: =HLOOKUP(H$9,'Target Marketing Revenue'!$E$63:$P$71,$A26,FALSE) -> 0 | I26: =IFERROR(H26/D26-1,0) -> 0 | J26: =IFERROR(H26/E26-1,0) -> 0
A27: 6 | B27: ='Target Marketing Revenue'!B68 -> 0 | C27: 0 | F27: =IFERROR(E27/D27,0) -> 0 | H27: =HLOOKUP(H$9,'Target Marketing Revenue'!$E$63:$P$71,$A27,FALSE) -> 0 | I27: =IFERROR(H27/D27-1,0) -> 0 | J27: =IFERROR(H27/E27-1,0) -> 0
A28: 4 | C28: 0
B29: ="TOTAL"&" "&B22 -> TOTAL MARKETING REVENUE (in Rp Bio) | C29: =SUM(C23:C28) -> 0 | D29: =SUM(D23:D28) -> 0 | E29: =SUM(E23:E28) -> 0 | F29: =IFERROR(E29/D29,0) -> 0 | H29: =SUM(H23:H28) -> 0 | I29: =IFERROR(H29/D29-1,0) -> 0 | J29: =IFERROR(H29/E29-1,0) -> 0 | L29: =SUM(L23:L28) -> 0 | N29: =SUM(N23:N28) -> 0
B31: DEVELOPMENT & OPERATIONAL COST
B32: PROJECT COST
B33: Land Cost | C33: 0
A34: 1 | B34: Land Acquisition Cost | F34: =IFERROR(E34/D34,0) -> 0 | H34: =HLOOKUP($H$9,'Dev&Land Budget Plan Cost'!$M$73:$X$84,'Dev&Land Budget Plan Cost'!$C74,FALSE) -> 0 | I34: =IFERROR(H34/D34-1,0) -> 0 | J34: =IFERROR(H34/E34-1,0) -> 0
A35: 2 | B35: Land Preparation Cost | F35: =IFERROR(E35/D35,0) -> 0 | H35: =HLOOKUP($H$9,'Dev&Land Budget Plan Cost'!$M$73:$X$84,'Dev&Land Budget Plan Cost'!$C75,FALSE) -> 0 | I35: =IFERROR(H35/D35-1,0) -> 0 | J35: =IFERROR(H35/E35-1,0) -> 0
B36: Taxes on Land Acquisition | F36: =IFERROR(E36/D36,0) -> 0 | I36: =IFERROR(H36/D36-1,0) -> 0 | J36: =IFERROR(H36/E36-1,0) -> 0
B37: Hard Cost | C37: 0
A38: 3 | B38: Development Cost | F38: =IFERROR(E38/D38,0) -> 0 | I38: =IFERROR(H38/D38-1,0) -> 0 | J38: =IFERROR(H38/E38-1,0) -> 0
B39: Preliminaries | F39: =IFERROR(E39/D39,0) -> 0 | H39: =HLOOKUP($H$9,'Dev&Land Budget Plan Cost'!$M$73:$X$84,'Dev&Land Budget Plan Cost'!$C76,FALSE) -> 0 | I39: =IFERROR(H39/D39-1,0) -> 0 | J39: =IFERROR(H39/E39-1,0) -> 0
B40: Pre-Construction | F40: =IFERROR(E40/D40,0) -> 0 | H40: =HLOOKUP($H$9,'Dev&Land Budget Plan Cost'!$M$73:$X$84,'Dev&Land Budget Plan Cost'!$C77,FALSE) -> 0 | I40: =IFERROR(H40/D40-1,0) -> 0 | J40: =IFERROR(H40/E40-1,0) -> 0
B41: Construction Cost | F41: =IFERROR(E41/D41,0) -> 0 | H41: =HLOOKUP($H$9,'Dev&Land Budget Plan Cost'!$M$73:$X$84,'Dev&Land Budget Plan Cost'!$C78,FALSE) -> 0 | I41: =IFERROR(H41/D41-1,0) -> 0 | J41: =IFERROR(H41/E41-1,0) -> 0
B42: Parking Construction Cost | F42: =IFERROR(E42/D42,0) -> 0 | H42: =HLOOKUP($H$9,'Dev&Land Budget Plan Cost'!$M$73:$X$84,'Dev&Land Budget Plan Cost'!$C79,FALSE) -> 0 | I42: =IFERROR(H42/D42-1,0) -> 0 | J42: =IFERROR(H42/E42-1,0) -> 0
B43: Infrastructure Cost | F43: =IFERROR(E43/D43,0) -> 0 | H43: =HLOOKUP($H$9,'Dev&Land Budget Plan Cost'!$M$73:$X$84,'Dev&Land Budget Plan Cost'!$C80,FALSE) -> 0 | I43: =IFERROR(H43/D43-1,0) -> 0 | J43: =IFERROR(H43/E43-1,0) -> 0
B44: Facilities Construction Cost | F44: =IFERROR(E44/D44,0) -> 0 | H44: =HLOOKUP($H$9,'Dev&Land Budget Plan Cost'!$M$73:$X$84,'Dev&Land Budget Plan Cost'!$C81,FALSE) -> 0 | I44: =IFERROR(H44/D44-1,0) -> 0 | J44: =IFERROR(H44/E44-1,0) -> 0
B45: Main Gate Construction Cost | F45: =IFERROR(E45/D45,0) -> 0 | H45: =HLOOKUP($H$9,'Dev&Land Budget Plan Cost'!$M$73:$X$84,'Dev&Land Budget Plan Cost'!$C82,FALSE) -> 0 | I45: =IFERROR(H45/D45-1,0) -> 0 | J45: =IFERROR(H45/E45-1,0) -> 0
...

Sheet SUMMARY BUDGET
A1: SUMMARY TARGET MARKETING REVENEUE & BUDGET COST
A2: ENTITAS: | B2: Pilih Perusahaan
A3: PROJECT | B3: Pilih Project
A4: BUDGET YEARS | B4: BUDGET 2027
A5: MONTH: | B5: YTD SEP
B7: Description | C7: 2020 | D7: BUDGET | E7: ACTUAL | F7: Budget Realization | H7: BUDGET | I7: Budget 2026 vs Budget 2027 | J7: Budget 2027 vs Actual 2026
C8: ACTUAL | D8: 2026 | E8: 2026 | F8: 2026 | H8: 2027 | I8: B2026 vs B2027 | J8: B2027 vs A2026
C9: YTD DEC | D9: YTD DEC | E9: YTD DEC | F9: =E9 -> YTD DEC | H9: YTD DEC | I9: YTD DEC | J9: YTD DEC
B10: TARGET MARKETING REVENUE (in Unit)
A12: 2 | B12: ='Target Marketing Revenue'!B54 -> 0 | F12: =IFERROR(E12/D12,0) -> 0 | H12: =HLOOKUP(H$9,'Target Marketing Revenue'!$E$42:$P$51,$A12,FALSE) -> 0 | I12: =IFERROR(H12/D12-1,0) -> 0 | J12: =IFERROR(H12/E12-1,0) -> 0
A13: 3 | B13: ='Target Marketing Revenue'!B55 -> 0 | F13: =IFERROR(E13/D13,0) -> 0 | H13: =HLOOKUP(H$9,'Target Marketing Revenue'!$E$42:$P$51,$A13,FALSE) -> 0 | I13: =IFERROR(H13/D13-1,0) -> 0 | J13: =IFERROR(H13/E13-1,0) -> 0
A14: 4 | B14: ='Target Marketing Revenue'!B56 -> 0 | F14: =IFERROR(E14/D14,0) -> 0 | H14: =HLOOKUP(H$9,'Target Marketing Revenue'!$E$42:$P$51,$A14,FALSE) -> 0 | I14: =IFERROR(H14/D14-1,0) -> 0 | J14: =IFERROR(H14/E14-1,0) -> 0
A15: 5 | B15: ='Target Marketing Revenue'!B57 -> 0 | F15: =IFERROR(E15/D15,0) -> 0 | H15: =HLOOKUP(H$9,'Target Marketing Revenue'!$E$42:$P$51,$A15,FALSE) -> 0 | I15: =IFERROR(H15/D15-1,0) -> 0 | J15: =IFERROR(H15/E15-1,0) -> 0
A16: 6 | B16: ='Target Marketing Revenue'!B58 -> 0 | F16: =IFERROR(E16/D16,0) -> 0 | H16: =HLOOKUP(H$9,'Target Marketing Revenue'!$E$42:$P$51,$A16,FALSE) -> 0 | I16: =IFERROR(H16/D16-1,0) -> 0 | J16: =IFERROR(H16/E16-1,0) -> 0
B17: TOTAL TARGET MARKETING REVENUE (in Unit) | C17: =SUM(C12:C16) -> 0 | D17: =SUM(D12:D16) -> 0 | E17: =SUM(E12:E16) -> 0 | F17: =IFERROR(E17/D17,0) -> 0 | H17: =SUM(H12:H16) -> 0 | I17: =IFERROR(H17/D17-1,0) -> 0 | J17: =IFERROR(H17/E17-1,0) -> 0
B19: TARGET MARKETING REVENUE (in Rp Bio)
A20: 2 | C20: 0 | F20: =IFERROR(E20/D20,0) -> 0 | H20: =HLOOKUP(H$9,'Target Marketing Revenue'!$E$63:$P$71,$A20,FALSE) -> 0 | I20: =IFERROR(H20/D20-1,0) -> 0 | J20: =IFERROR(H20/E20-1,0) -> 0
A21: 3 | B21: ='Target Marketing Revenue'!B64 -> 0 | F21: =IFERROR(E21/D21,0) -> 0 | H21: =HLOOKUP(H$9,'Target Marketing Revenue'!$E$63:$P$71,$A21,FALSE) -> 0 | I21: =IFERROR(H21/D21-1,0) -> 0 | J21: =IFERROR(H21/E21-1,0) -> 0
A22: 4 | B22: ='Target Marketing Revenue'!B65 -> 0 | F22: =IFERROR(E22/D22,0) -> 0 | H22: =HLOOKUP(H$9,'Target Marketing Revenue'!$E$63:$P$71,$A22,FALSE) -> 0 | I22: =IFERROR(H22/D22-1,0) -> 0 | J22: =IFERROR(H22/E22-1,0) -> 0
A23: 5 | B23: ='Target Marketing Revenue'!B66 -> 0 | C23: 0 | F23: =IFERROR(E23/D23,0) -> 0 | H23: =HLOOKUP(H$9,'Target Marketing Revenue'!$E$63:$P$71,$A23,FALSE) -> 0 | I23: =IFERROR(H23/D23-1,0) -> 0 | J23: =IFERROR(H23/E23-1,0) -> 0
A24: 6 | B24: ='Target Marketing Revenue'!B67 -> 0 | C24: 0 | F24: =IFERROR(E24/D24,0) -> 0 | H24: =HLOOKUP(H$9,'Target Marketing Revenue'!$E$63:$P$71,$A24,FALSE) -> 0 | I24: =IFERROR(H24/D24-1,0) -> 0 | J24: =IFERROR(H24/E24-1,0) -> 0
B25: TOTAL TARGET MARKETING REVENUE (in Rp Bio) | C25: =SUM(C19:C24) -> 0 | D25: =SUM(D19:D24) -> 0 | E25: =SUM(E19:E24) -> 0 | F25: =IFERROR(E25/D25,0) -> 0 | H25: =SUM(H19:H24) -> 0 | I25: =IFERROR(H25/D25-1,0) -> 0 | J25: =IFERROR(H25/E25-1,0) -> 0
B27: DEVELOPMENT & OPERATIONAL COST
B28: PROJECT COST
B29: Land Cost | C29: 0 | D29: =SUM(D30:D32) -> 0 | E29: =SUM(E30:E32) -> 0 | H29: =SUM(H30:H32) -> 0
A30: 1 | B30: Land Acquisition Cost | F30: =IFERROR(E30/D30,0) -> 0 | H30: =HLOOKUP($H$9,'Dev&Land Budget Plan Cost'!$M$73:$X$84,'Dev&Land Budget Plan Cost'!$C74,FALSE) -> 0 | I30: =IFERROR(H30/D30-1,0) -> 0 | J30: =IFERROR(H30/E30-1,0) -> 0
A31: 2 | B31: Land Preparation Cost | F31: =IFERROR(E31/D31,0) -> 0 | H31: =HLOOKUP($H$9,'Dev&Land Budget Plan Cost'!$M$73:$X$84,'Dev&Land Budget Plan Cost'!$C75,FALSE) -> 0 | I31: =IFERROR(H31/D31-1,0) -> 0 | J31: =IFERROR(H31/E31-1,0) -> 0
B32: Taxes on Land Acquisition | F32: =IFERROR(E32/D32,0) -> 0 | I32: =IFERROR(H32/D32-1,0) -> 0 | J32: =IFERROR(H32/E32-1,0) -> 0
B33: Hard Cost | C33: 0 | D33: =SUM(D34:D41) -> 0 | E33: =SUM(E34:E41) -> 0 | H33: =SUM(H34:H41) -> 0
A34: 3 | B34: Development Cost | F34: =IFERROR(E34/D34,0) -> 0 | I34: =IFERROR(H34/D34-1,0) -> 0 | J34: =IFERROR(H34/E34-1,0) -> 0
B35: Preliminaries | F35: =IFERROR(E35/D35,0) -> 0 | H35: =HLOOKUP($H$9,'Dev&Land Budget Plan Cost'!$M$73:$X$84,'Dev&Land Budget Plan Cost'!$C76,FALSE) -> 0 | I35: =IFERROR(H35/D35-1,0) -> 0 | J35: =IFERROR(H35/E35-1,0) -> 0
B36: Pre-Construction | F36: =IFERROR(E36/D36,0) -> 0 | H36: =HLOOKUP($H$9,'Dev&Land Budget Plan Cost'!$M$73:$X$84,'Dev&Land Budget Plan Cost'!$C77,FALSE) -> 0 | I36: =IFERROR(H36/D36-1,0) -> 0 | J36: =IFERROR(H36/E36-1,0) -> 0
B37: Construction Cost | F37: =IFERROR(E37/D37,0) -> 0 | H37: =HLOOKUP($H$9,'Dev&Land Budget Plan Cost'!$M$73:$X$84,'Dev&Land Budget Plan Cost'!$C78,FALSE) -> 0 | I37: =IFERROR(H37/D37-1,0) -> 0 | J37: =IFERROR(H37/E37-1,0) -> 0
B38: Parking Construction Cost | F38: =IFERROR(E38/D38,0) -> 0 | H38: =HLOOKUP($H$9,'Dev&Land Budget Plan Cost'!$M$73:$X$84,'Dev&Land Budget Plan Cost'!$C79,FALSE) -> 0 | I38: =IFERROR(H38/D38-1,0) -> 0 | J38: =IFERROR(H38/E38-1,0) -> 0
B39: Infrastructure Cost | F39: =IFERROR(E39/D39,0) -> 0 | H39: =HLOOKUP($H$9,'Dev&Land Budget Plan Cost'!$M$73:$X$84,'Dev&Land Budget Plan Cost'!$C80,FALSE) -> 0 | I39: =IFERROR(H39/D39-1,0) -> 0 | J39: =IFERROR(H39/E39-1,0) -> 0
B40: Facilities Construction Cost | F40: =IFERROR(E40/D40,0) -> 0 | H40: =HLOOKUP($H$9,'Dev&Land Budget Plan Cost'!$M$73:$X$84,'Dev&Land Budget Plan Cost'!$C81,FALSE) -> 0 | I40: =IFERROR(H40/D40-1,0) -> 0 | J40: =IFERROR(H40/E40-1,0) -> 0
B41: Main Gate Construction Cost | F41: =IFERROR(E41/D41,0) -> 0 | H41: =HLOOKUP($H$9,'Dev&Land Budget Plan Cost'!$M$73:$X$84,'Dev&Land Budget Plan Cost'!$C82,FALSE) -> 0 | I41: =IFERROR(H41/D41-1,0) -> 0 | J41: =IFERROR(H41/E41-1,0) -> 0
F42: =IFERROR(E42/D42,0) -> 0 | I42: =IFERROR(H42/D42-1,0) -> 0 | J42: =IFERROR(H42/E42-1,0) -> 0
B43: Soft Cost | C43: 0 | D43: =SUM(D44:D45) -> 0 | E43: =SUM(E44:E45) -> 0 | H43: =SUM(H44:H45) -> 0
A44: 7 | B44: Legal, License & Permits | F44: =IFERROR(E44/D44,0) -> 0 | H44: =HLOOKUP($H$9,'Dev&Land Budget Plan Cost'!$M$73:$X$84,'Dev&Land Budget Plan Cost'!$C83,FALSE) -> 0 | I44: =IFERROR(H44/D44-1,0) -> 0 | J44: =IFERROR(H44/E44-1,0) -> 0
...

Sheet SUM Marketing Revenue
A1: SUMMARY TARGET SALES
A2: ENTITAS: | B2: Pilih Perusahaan
A3: PROJECT | B3: Pilih Project
A4: BUDGET YEARS | B4: BUDGET 2026
A5: MONTH: | B5: YTD SEP
B7: Description | C7: 2020 | D7: BUDGET | E7: ACTUAL | F7: Budget Realization | H7: BUDGET | I7: Budget 2025 vs Budget 2026 | J7: Budget 2026 vs Actual 2025
C8: ACTUAL | D8: 2025 | E8: 2025 | F8: 2025 | H8: 2026 | I8: B2025 vs B2026 | J8: B2026 vs A2025
C9: YTD DEC | D9: YTD DEC | E9: YTD DEC | F9: =E9 -> YTD DEC | H9: YTD DEC | I9: YTD DEC | J9: YTD DEC
B11: SALES
A13: 1 | B13: in SQM
A14: 2 | B14: ='Target Marketing Revenue'!B54 -> 0 | C14: 0 | F14: =IFERROR(E14/D14,0) -> 0 | H14: =HLOOKUP(H$9,'Target Marketing Revenue'!$E$53:$P$61,$A14,FALSE) -> 0 | I14: =IFERROR(H14/D14-1,0) -> 0 | J14: =IFERROR(H14/E14-1,0) -> 0
A15: 3 | B15: ='Target Marketing Revenue'!B55 -> 0 | F15: =IFERROR(E15/D15,0) -> 0 | H15: =HLOOKUP(H$9,'Target Marketing Revenue'!$E$53:$P$61,$A15,FALSE) -> 0 | I15: =IFERROR(H15/D15-1,0) -> 0 | J15: =IFERROR(H15/E15-1,0) -> 0
A16: 4 | B16: ='Target Marketing Revenue'!B56 -> 0 | F16: =IFERROR(E16/D16,0) -> 0 | H16: =HLOOKUP(H$9,'Target Marketing Revenue'!$E$53:$P$61,$A16,FALSE) -> 0 | I16: =IFERROR(H16/D16-1,0) -> 0 | J16: =IFERROR(H16/E16-1,0) -> 0
A17: 5 | B17: ='Target Marketing Revenue'!B57 -> 0 | C17: 0 | F17: =IFERROR(E17/D17,0) -> 0 | H17: =HLOOKUP(H$9,'Target Marketing Revenue'!$E$53:$P$61,$A17,FALSE) -> 0 | I17: =IFERROR(H17/D17-1,0) -> 0 | J17: =IFERROR(H17/E17-1,0) -> 0
A18: 6 | B18: ='Target Marketing Revenue'!B58 -> 0 | C18: 0 | F18: =IFERROR(E18/D18,0) -> 0 | H18: =HLOOKUP(H$9,'Target Marketing Revenue'!$E$53:$P$61,$A18,FALSE) -> 0 | I18: =IFERROR(H18/D18-1,0) -> 0 | J18: =IFERROR(H18/E18-1,0) -> 0
C19: 0
B20: ="TOTAL"&" "&B11&" "&B13 -> TOTAL SALES in SQM | C20: =SUM(C14:C19) -> 0 | D20: =SUM(D14:D19) -> 0 | E20: =SUM(E14:E19) -> 0 | F20: =IFERROR(E20/D20,0) -> 0 | H20: =SUM(H14:H19) -> 0 | I20: =IFERROR(H20/D20-1,0) -> 0 | J20: =IFERROR(H20/E20-1,0) -> 0
A22: 1 | B22: MARKETING REVENUE (in Rp Bio)
A23: 2 | B23: ='Target Marketing Revenue'!B64 -> 0 | C23: 0 | F23: =IFERROR(E23/D23,0) -> 0 | H23: =HLOOKUP(H$9,'Target Marketing Revenue'!$E$63:$P$71,$A23,FALSE) -> 0 | I23: =IFERROR(H23/D23-1,0) -> 0 | J23: =IFERROR(H23/E23-1,0) -> 0
A24: 3 | B24: ='Target Marketing Revenue'!B65 -> 0 | F24: =IFERROR(E24/D24,0) -> 0 | H24: =HLOOKUP(H$9,'Target Marketing Revenue'!$E$63:$P$71,$A24,FALSE) -> 0 | I24: =IFERROR(H24/D24-1,0) -> 0 | J24: =IFERROR(H24/E24-1,0) -> 0
A25: 4 | B25: ='Target Marketing Revenue'!B66 -> 0 | F25: =IFERROR(E25/D25,0) -> 0 | H25: =HLOOKUP(H$9,'Target Marketing Revenue'!$E$63:$P$71,$A25,FALSE) -> 0 | I25: =IFERROR(H25/D25-1,0) -> 0 | J25: =IFERROR(H25/E25-1,0) -> 0
A26: 5 | B26: ='Target Marketing Revenue'!B67 -> 0 | C26: 0 | F26: =IFERROR(E26/D26,0) -> 0 | H26: =HLOOKUP(H$9,'Target Marketing Revenue'!$E$63:$P$71,$A26,FALSE) -> 0 | I26: =IFERROR(H26/D26-1,0) -> 0 | J26: =IFERROR(H26/E26-1,0) -> 0
A27: 6 | B27: ='Target Marketing Revenue'!B68 -> 0 | C27: 0 | F27: =IFERROR(E27/D27,0) -> 0 | H27: =HLOOKUP(H$9,'Target Marketing Revenue'!$E$63:$P$71,$A27,FALSE) -> 0 | I27: =IFERROR(H27/D27-1,0) -> 0 | J27: =IFERROR(H27/E27-1,0) -> 0
A28: 4 | C28: 0
B29: ="TOTAL"&" "&B22 -> TOTAL MARKETING REVENUE (in Rp Bio) | C29: =SUM(C23:C28) -> 0 | D29: =SUM(D23:D28) -> 0 | E29: =SUM(E23:E28) -> 0 | F29: =IFERROR(E29/D29,0) -> 0 | H29: =SUM(H23:H28) -> 0 | I29: =IFERROR(H29/D29-1,0) -> 0 | J29: =IFERROR(H29/E29-1,0) -> 0

Sheet Target Marketing Revenue
B1: Target Marketing Revenue
B2: ENTITAS: | C2: Pilih Perusahaan
B3: PROJECT | C3: Pilih Project
B4: BUDGET YEARS | C4: 2027
B6: Target Marketing Revenue (Unit) | C6: Stock Unit 1 Ags 2026 | D6: Marketing Revenue in Unit | E6: 46388 | F6: 46419 | G6: 46447 | H6: 46478 | I6: 46508 | J6: 46539 | K6: 46569 | L6: 46600 | M6: 46631 | N6: 46661 | O6: 46692 | P6: 46722
D7: =SUM(E7:P7) -> 0
D8: =SUM(E8:P8) -> 0
D9: =SUM(E9:P9) -> 0
D10: =SUM(E10:P10) -> 0
D11: =SUM(E11:P11) -> 0
D12: =SUM(E12:P12) -> 0
D13: =SUM(E13:P13) -> 0
D14: =SUM(E14:P14) -> 0
B15: ="TOTAL"&" "&B6 -> TOTAL Target Marketing Revenue (Unit) | C15: =SUM(C7:C14) -> 0 | D15: =SUM(D7:D14) -> 0 | E15: =SUM(E7:E14) -> 0 | F15: =SUM(F7:F14) -> 0 | G15: =SUM(G7:G14) -> 0 | H15: =SUM(H7:H14) -> 0 | I15: =SUM(I7:I14) -> 0 | J15: =SUM(J7:J14) -> 0 | ... P15: =SUM(P7:P14) -> 0
B18: Target Marketing Revenue in (Sqm) | C18: Stock SQM 1 Ags 2026 | D18: Marketing Revenue in SQM | E18: =E6 -> 46388 | F18: =F6 -> 46419 | G18: =G6 -> 46447 | H18: =H6 -> 46478 | I18: =I6 -> 46508 | J18: =J6 -> 46539 | K18: =K6 -> 46569 | L18: =L6 -> 46600 | ... P18: =P6 -> 46722
D19: =SUM(E19:P19) -> 0
D20: =SUM(E20:P20) -> 0
D21: =SUM(E21:P21) -> 0
D22: =SUM(E22:P22) -> 0
D23: =SUM(E23:P23) -> 0
D24: =SUM(E24:P24) -> 0
D25: =SUM(E25:P25) -> 0
D26: =SUM(E26:P26) -> 0
B27: ="TOTAL"&" "&B18 -> TOTAL Target Marketing Revenue in (Sqm) | C27: =SUM(C19:C26) -> 0 | D27: =SUM(D19:D26) -> 0 | E27: =SUM(E19:E26) -> 0 | F27: =SUM(F19:F26) -> 0 | G27: =SUM(G19:G26) -> 0 | H27: =SUM(H19:H26) -> 0 | I27: =SUM(I19:I26) -> 0 | J27: =SUM(J19:J26) -> 0 | ... P27: =SUM(P19:P26) -> 0
C29: Hard cash
B30: Target Marketing Revenue VALUE | C30: Price / sqm (Rp.)* | D30: TOTAL SALES VALUE | E30: =E18 -> 46388 | F30: =F18 -> 46419 | G30: =G18 -> 46447 | H30: =H18 -> 46478 | I30: =I18 -> 46508 | J30: =J18 -> 46539 | K30: =K18 -> 46569 | L30: =L18 -> 46600 | ... P30: =P18 -> 46722
D31: =SUM(E31:P31) -> 0 | E31: =$C31*E19 -> 0 | F31: =$C31*F19 -> 0 | G31: =$C31*G19 -> 0 | H31: =$C31*H19 -> 0 | I31: =$C31*I19 -> 0 | J31: =$C31*J19 -> 0 | K31: =$C31*K19 -> 0 | L31: =$C31*L19 -> 0 | ... P31: =$C31*P19 -> 0
D32: =SUM(E32:P32) -> 0 | E32: =$C32*E20 -> 0 | F32: =$C32*F20 -> 0 | G32: =$C32*G20 -> 0 | H32: =$C32*H20 -> 0 | I32: =$C32*I20 -> 0 | J32: =$C32*J20 -> 0 | K32: =$C32*K20 -> 0 | L32: =$C32*L20 -> 0 | ... P32: =$C32*P20 -> 0
D33: =SUM(E33:P33) -> 0 | E33: =$C33*E21 -> 0 | F33: =$C33*F21 -> 0 | G33: =$C33*G21 -> 0 | H33: =$C33*H21 -> 0 | I33: =$C33*I21 -> 0 | J33: =$C33*J21 -> 0 | K33: =$C33*K21 -> 0 | L33: =$C33*L21 -> 0 | ... P33: =$C33*P21 -> 0
D34: =SUM(E34:P34) -> 0 | E34: =$C34*E22 -> 0 | F34: =$C34*F22 -> 0 | G34: =$C34*G22 -> 0 | H34: =$C34*H22 -> 0 | I34: =$C34*I22 -> 0 | J34: =$C34*J22 -> 0 | K34: =$C34*K22 -> 0 | L34: =$C34*L22 -> 0 | ... P34: =$C34*P22 -> 0
D35: =SUM(E35:P35) -> 0 | E35: =$C35*E23 -> 0 | F35: =$C35*F23 -> 0 | G35: =$C35*G23 -> 0 | H35: =$C35*H23 -> 0 | I35: =$C35*I23 -> 0 | J35: =$C35*J23 -> 0 | K35: =$C35*K23 -> 0 | L35: =$C35*L23 -> 0 | ... P35: =$C35*P23 -> 0
D36: =SUM(E36:P36) -> 0 | E36: =$C36*E24 -> 0 | F36: =$C36*F24 -> 0 | G36: =$C36*G24 -> 0 | H36: =$C36*H24 -> 0 | I36: =$C36*I24 -> 0 | J36: =$C36*J24 -> 0 | K36: =$C36*K24 -> 0 | L36: =$C36*L24 -> 0 | ... P36: =$C36*P24 -> 0
D37: =SUM(E37:P37) -> 0 | E37: =$C37*E25 -> 0 | F37: =$C37*F25 -> 0 | G37: =$C37*G25 -> 0 | H37: =$C37*H25 -> 0 | I37: =$C37*I25 -> 0 | J37: =$C37*J25 -> 0 | K37: =$C37*K25 -> 0 | L37: =$C37*L25 -> 0 | ... P37: =$C37*P25 -> 0
D38: =SUM(E38:P38) -> 0 | E38: =$C38*E26 -> 0 | F38: =$C38*F26 -> 0 | G38: =$C38*G26 -> 0 | H38: =$C38*H26 -> 0 | I38: =$C38*I26 -> 0 | J38: =$C38*J26 -> 0 | K38: =$C38*K26 -> 0 | L38: =$C38*L26 -> 0 | ... P38: =$C38*P26 -> 0
B39: ="TOTAL"&" "&B30 -> TOTAL Target Marketing Revenue VALUE | D39: =SUM(D31:D38) -> 0 | E39: =SUM(E31:E38) -> 0 | F39: =SUM(F31:F38) -> 0 | G39: =SUM(G31:G38) -> 0 | H39: =SUM(H31:H38) -> 0 | I39: =SUM(I31:I38) -> 0 | J39: =SUM(J31:J38) -> 0 | K39: =SUM(K31:K38) -> 0 | ... P39: =SUM(P31:P38) -> 0
B40: * Price / sqm diisi dengan asumsi cara bayar Cash Keras
B42: Linked to SUM Actual vs Budget | E42: YTD JAN | F42: YTD FEB | G42: YTD MAR | H42: YTD APR | I42: YTD MAY | J42: YTD JUN | K42: YTD JUL | L42: YTD AUG | M42: YTD SEP | N42: YTD OCT | O42: YTD NOV | P42: YTD DEC
B43: =B6 -> Target Marketing Revenue (Unit)
B44: =B7 -> 0 | E44: =SUM($E7:E7) -> 0 | F44: =SUM($E7:F7) -> 0 | G44: =SUM($E7:G7) -> 0 | H44: =SUM($E7:H7) -> 0 | I44: =SUM($E7:I7) -> 0 | J44: =SUM($E7:J7) -> 0 | K44: =SUM($E7:K7) -> 0 | L44: =SUM($E7:L7) -> 0 | ... P44: =SUM($E7:P7) -> 0
B45: =B8 -> 0 | E45: =SUM($E8:E8) -> 0 | F45: =SUM($E8:F8) -> 0 | G45: =SUM($E8:G8) -> 0 | H45: =SUM($E8:H8) -> 0 | I45: =SUM($E8:I8) -> 0 | J45: =SUM($E8:J8) -> 0 | K45: =SUM($E8:K8) -> 0 | L45: =SUM($E8:L8) -> 0 | ... P45: =SUM($E8:P8) -> 0
...

Sheet Budget Sales Cost
B1: BUDGET SALES COST
B2: ENTITAS: | C2: Pilih Perusahaan
B3: PROJECT | C3: Pilih Project
B4: BUDGET YEARS | C4: 2027
C6: 46388 | D6: 46419 | E6: 46447 | F6: 46478 | G6: 46508 | H6: 46539 | I6: 46569 | J6: 46600 | K6: 46631 | L6: 46661 | M6: 46692 | N6: 46722 | O6: TOTAL
B7: ='Target Marketing Revenue'!B39 -> TOTAL Target Marketing Revenue VALUE | C7: ='Target Marketing Revenue'!E39 -> 0 | D7: ='Target Marketing Revenue'!F39 -> 0 | E7: ='Target Marketing Revenue'!G39 -> 0 | F7: ='Target Marketing Revenue'!H39 -> 0 | G7: ='Target Marketing Revenue'!I39 -> 0 | H7: ='Target Marketing Revenue'!J39 -> 0 | I7: ='Target Marketing Revenue'!K39 -> 0 | J7: ='Target Marketing Revenue'!L39 -> 0 | ... N7: ='Target Marketing Revenue'!P39 -> 0 | O7: =SUM(C7:N7) -> 0
B9: SALES COST
B10: SALES INHOUSE | C10: =C25 -> 0 | D10: =D25 -> 0 | E10: =E25 -> 0 | F10: =F25 -> 0 | G10: =G25 -> 0 | H10: =H25 -> 0 | I10: =I25 -> 0 | J10: =J25 -> 0 | ... N10: =N25 -> 0 | O10: =SUM(C10:N10) -> 0
B11: SALES AGENT | C11: =C36 -> 0 | D11: =D36 -> 0 | E11: =E36 -> 0 | F11: =F36 -> 0 | G11: =G36 -> 0 | H11: =H36 -> 0 | I11: =I36 -> 0 | J11: =J36 -> 0 | ... N11: =N36 -> 0 | O11: =SUM(C11:N11) -> 0
B13: TOTAL SALES COST | C13: =SUM(C10:C11) -> 0 | D13: =SUM(D10:D11) -> 0 | E13: =SUM(E10:E11) -> 0 | F13: =SUM(F10:F11) -> 0 | G13: =SUM(G10:G11) -> 0 | H13: =SUM(H10:H11) -> 0 | I13: =SUM(I10:I11) -> 0 | J13: =SUM(J10:J11) -> 0 | ... O13: =SUM(O10:O11) -> 0
B14: % ratio to Target Sales | C14: =C13/C7 -> #DIV/0! | D14: =D13/D7 -> #DIV/0! | E14: =E13/E7 -> #DIV/0! | F14: =F13/F7 -> #DIV/0! | G14: =G13/G7 -> #DIV/0! | H14: =H13/H7 -> #DIV/0! | I14: =I13/I7 -> #DIV/0! | J14: =J13/J7 -> #DIV/0! | ... N14: =N13/N7 -> #DIV/0!
B17: Sales Cost (In House) | C17: =C6 -> 46388 | D17: =D6 -> 46419 | E17: =E6 -> 46447 | F17: =F6 -> 46478 | G17: =G6 -> 46508 | H17: =H6 -> 46539 | I17: =I6 -> 46569 | J17: =J6 -> 46600 | ... N17: =N6 -> 46722
B18: Closing Fee
B19: OR
B20: Komisi
B21: Reward Sales
B25: ="Total"&" "&B17 -> Total Sales Cost (In House) | C25: =SUM(C18:C24) -> 0 | D25: =SUM(D18:D24) -> 0 | E25: =SUM(E18:E24) -> 0 | F25: =SUM(F18:F24) -> 0 | G25: =SUM(G18:G24) -> 0 | H25: =SUM(H18:H24) -> 0 | I25: =SUM(I18:I24) -> 0 | J25: =SUM(J18:J24) -> 0 | ... N25: =SUM(N18:N24) -> 0
B28: Sales Cost (Agent) | C28: =C6 -> 46388 | D28: =D6 -> 46419 | E28: =E6 -> 46447 | F28: =F6 -> 46478 | G28: =G6 -> 46508 | H28: =H6 -> 46539 | I28: =I6 -> 46569 | J28: =J6 -> 46600 | ... N28: =N6 -> 46722
B29: Closing Fee
B30: OR
B31: Komisi
B36: ="Total"&" "&B28 -> Total Sales Cost (Agent) | C36: =SUM(C29:C35) -> 0 | D36: =SUM(D29:D35) -> 0 | E36: =SUM(E29:E35) -> 0 | F36: =SUM(F29:F35) -> 0 | G36: =SUM(G29:G35) -> 0 | H36: =SUM(H29:H35) -> 0 | I36: =SUM(I29:I35) -> 0 | J36: =SUM(J29:J35) -> 0 | ... N36: =SUM(N29:N35) -> 0
B40: Linked to SUM Actual vs Budget | C40: YTD JAN | D40: YTD FEB | E40: YTD MAR | F40: YTD APR | G40: YTD MAY | H40: YTD JUN | I40: YTD JUL | J40: YTD AUG | K40: YTD SEP | L40: YTD OCT | M40: YTD NOV | N40: YTD DEC
B41: =B10 -> SALES INHOUSE | C41: =SUM($C10:C10) -> 0 | D41: =SUM($C10:D10) -> 0 | E41: =SUM($C10:E10) -> 0 | F41: =SUM($C10:F10) -> 0 | G41: =SUM($C10:G10) -> 0 | H41: =SUM($C10:H10) -> 0 | I41: =SUM($C10:I10) -> 0 | J41: =SUM($C10:J10) -> 0 | ... N41: =SUM($C10:N10) -> 0
B42: =B11 -> SALES AGENT | C42: =SUM($C11:C11) -> 0 | D42: =SUM($C11:D11) -> 0 | E42: =SUM($C11:E11) -> 0 | F42: =SUM($C11:F11) -> 0 | G42: =SUM($C11:G11) -> 0 | H42: =SUM($C11:H11) -> 0 | I42: =SUM($C11:I11) -> 0 | J42: =SUM($C11:J11) -> 0 | ... N42: =SUM($C11:N11) -> 0
B43: TOTAL SALES COST | C43: =SUM($C12:C12) -> 0 | D43: =SUM($C12:D12) -> 0 | E43: =SUM($C12:E12) -> 0 | F43: =SUM($C12:F12) -> 0 | G43: =SUM($C12:G12) -> 0 | H43: =SUM($C12:H12) -> 0 | I43: =SUM($C12:I12) -> 0 | J43: =SUM($C12:J12) -> 0 | ... N43: =SUM($C12:N12) -> 0

Sheet Budget Program Sales
B1: PROGRAM SALES
B2: ENTITAS: | C2: Pilih Perusahaan
B3: PROJECT | C3: Pilih Project
B4: BUDGET YEARS | C4: 2027
C6: 46388 | D6: 46419 | E6: 46447 | F6: 46478 | G6: 46508 | H6: 46539 | I6: 46569 | J6: 46600 | K6: 46631 | L6: 46661 | M6: 46692 | N6: 46722 | O6: TOTAL
B7: ='Target Marketing Revenue'!B39 -> TOTAL Target Marketing Revenue VALUE | C7: ='Target Marketing Revenue'!E39 -> 0 | D7: ='Target Marketing Revenue'!F39 -> 0 | E7: ='Target Marketing Revenue'!G39 -> 0 | F7: ='Target Marketing Revenue'!H39 -> 0 | G7: ='Target Marketing Revenue'!I39 -> 0 | H7: ='Target Marketing Revenue'!J39 -> 0 | I7: ='Target Marketing Revenue'!K39 -> 0 | J7: ='Target Marketing Revenue'!L39 -> 0 | ... N7: ='Target Marketing Revenue'!P39 -> 0 | O7: =SUM(C7:N7) -> 0
B9: PROGRAM SALES
B10: SUBSIDI BOOKING FEE | O10: =SUM(C10:N10) -> 0
B11: SUBSIDI DOWN PAYMENT
B12: SUBSIDI ANGSURAN | O12: =SUM(C12:N12) -> 0
B13: SUBSIDI AKAD | O13: =SUM(C13:N13) -> 0
B14: RENTBACK | O14: =SUM(C14:N14) -> 0 | P14: *Bukan nilai unit buybacknya tapi program rentback ini ada biaya investment yg harus dibayarkan developer ke konsumen masuk sini ( biaya interest , dll )
B15: CASHBACK PATUNGAN RUMAH | O15: =SUM(C15:N15) -> 0
O16: =SUM(C16:N16) -> 0 | P16: *Buyback tidak masuk budget >> masuk cashflow
O17: =SUM(C17:N17) -> 0
O18: =SUM(C18:N18) -> 0
B19: TOTAL SALES PROGRAM | C19: =SUM(C10:C18) -> 0 | D19: =SUM(D10:D18) -> 0 | E19: =SUM(E10:E18) -> 0 | F19: =SUM(F10:F18) -> 0 | G19: =SUM(G10:G18) -> 0 | H19: =SUM(H10:H18) -> 0 | I19: =SUM(I10:I18) -> 0 | J19: =SUM(J10:J18) -> 0 | ... O19: =SUM(O10:O18) -> 0
B20: % ratio to Target Sales | C20: =C19/C7 -> #DIV/0! | D20: =D19/D7 -> #DIV/0! | E20: =E19/E7 -> #DIV/0! | F20: =F19/F7 -> #DIV/0! | G20: =G19/G7 -> #DIV/0! | H20: =H19/H7 -> #DIV/0! | I20: =I19/I7 -> #DIV/0! | J20: =J19/J7 -> #DIV/0! | ... N20: =N19/N7 -> #DIV/0!
B26: Linked to SUM Budget Cost | C26: YTD JAN | D26: YTD FEB | E26: YTD MAR | F26: YTD APR | G26: YTD MAY | H26: YTD JUN | I26: YTD JUL | J26: YTD AUG | K26: YTD SEP | L26: YTD OCT | M26: YTD NOV | N26: YTD DEC
B27: =B10 -> SUBSIDI BOOKING FEE | C27: =SUM($C10:C10) -> 0 | D27: =SUM($C10:D10) -> 0 | E27: =SUM($C10:E10) -> 0 | F27: =SUM($C10:F10) -> 0 | G27: =SUM($C10:G10) -> 0 | H27: =SUM($C10:H10) -> 0 | I27: =SUM($C10:I10) -> 0 | J27: =SUM($C10:J10) -> 0 | ... N27: =SUM($C10:N10) -> 0
B28: SUBSIDI DOWN PAYMENT | C28: =SUM($C11:C11) -> 0 | D28: =SUM($C11:D11) -> 0 | E28: =SUM($C11:E11) -> 0 | F28: =SUM($C11:F11) -> 0 | G28: =SUM($C11:G11) -> 0 | H28: =SUM($C11:H11) -> 0 | I28: =SUM($C11:I11) -> 0 | J28: =SUM($C11:J11) -> 0 | ... N28: =SUM($C11:N11) -> 0
B29: =B12 -> SUBSIDI ANGSURAN | C29: =SUM($C12:C12) -> 0 | D29: =SUM($C12:D12) -> 0 | E29: =SUM($C12:E12) -> 0 | F29: =SUM($C12:F12) -> 0 | G29: =SUM($C12:G12) -> 0 | H29: =SUM($C12:H12) -> 0 | I29: =SUM($C12:I12) -> 0 | J29: =SUM($C12:J12) -> 0 | ... N29: =SUM($C12:N12) -> 0
B30: =B13 -> SUBSIDI AKAD | C30: =SUM($C13:C13) -> 0 | D30: =SUM($C13:D13) -> 0 | E30: =SUM($C13:E13) -> 0 | F30: =SUM($C13:F13) -> 0 | G30: =SUM($C13:G13) -> 0 | H30: =SUM($C13:H13) -> 0 | I30: =SUM($C13:I13) -> 0 | J30: =SUM($C13:J13) -> 0 | ... N30: =SUM($C13:N13) -> 0
B31: =B14 -> RENTBACK | C31: =SUM($C14:C14) -> 0 | D31: =SUM($C14:D14) -> 0 | E31: =SUM($C14:E14) -> 0 | F31: =SUM($C14:F14) -> 0 | G31: =SUM($C14:G14) -> 0 | H31: =SUM($C14:H14) -> 0 | I31: =SUM($C14:I14) -> 0 | J31: =SUM($C14:J14) -> 0 | ... N31: =SUM($C14:N14) -> 0
B32: =B15 -> CASHBACK PATUNGAN RUMAH | C32: =SUM($C15:C15) -> 0 | D32: =SUM($C15:D15) -> 0 | E32: =SUM($C15:E15) -> 0 | F32: =SUM($C15:F15) -> 0 | G32: =SUM($C15:G15) -> 0 | H32: =SUM($C15:H15) -> 0 | I32: =SUM($C15:I15) -> 0 | J32: =SUM($C15:J15) -> 0 | ... N32: =SUM($C15:N15) -> 0
B33: =B16 -> 0 | C33: =SUM($C16:C16) -> 0 | D33: =SUM($C16:D16) -> 0 | E33: =SUM($C16:E16) -> 0 | F33: =SUM($C16:F16) -> 0 | G33: =SUM($C16:G16) -> 0 | H33: =SUM($C16:H16) -> 0 | I33: =SUM($C16:I16) -> 0 | J33: =SUM($C16:J16) -> 0 | ... N33: =SUM($C16:N16) -> 0
B34: =B17 -> 0 | C34: =SUM($C17:C17) -> 0 | D34: =SUM($C17:D17) -> 0 | E34: =SUM($C17:E17) -> 0 | F34: =SUM($C17:F17) -> 0 | G34: =SUM($C17:G17) -> 0 | H34: =SUM($C17:H17) -> 0 | I34: =SUM($C17:I17) -> 0 | J34: =SUM($C17:J17) -> 0 | ... N34: =SUM($C17:N17) -> 0
B35: =B18 -> 0 | C35: =SUM($C18:C18) -> 0 | D35: =SUM($C18:D18) -> 0 | E35: =SUM($C18:E18) -> 0 | F35: =SUM($C18:F18) -> 0 | G35: =SUM($C18:G18) -> 0 | H35: =SUM($C18:H18) -> 0 | I35: =SUM($C18:I18) -> 0 | J35: =SUM($C18:J18) -> 0 | ... N35: =SUM($C18:N18) -> 0
B36: TOTAL SALES COST | C36: =SUM(C27:C35) -> 0 | D36: =SUM(D27:D35) -> 0 | E36: =SUM(E27:E35) -> 0 | F36: =SUM(F27:F35) -> 0 | G36: =SUM(G27:G35) -> 0 | H36: =SUM(H27:H35) -> 0 | I36: =SUM(I27:I35) -> 0 | J36: =SUM(J27:J35) -> 0 | ... N36: =SUM(N27:N35) -> 0

Sheet Budget Marketing Activity
A1: MARKETING BUDGET PLANNING
A3: ENTITAS: | B3: Pilih Perusahaan
A4: PROJECT: | B4: Pilih Project | E4: Total Sales TaSget (full yeaS) : | F4: ='Target Marketing Revenue'!D39 -> 0
A5: DIVISION: | E5: Total Marketing Expenses : | F5: =E104 -> 0
A6: BUDGET YEAR: | B6: 2027 | E6: Ratio of Mkt Expenses to Sales TaSget : | F6: =F5/F4 -> #DIV/0!
A8: Marketing Budget Plan | F8: 2027
A9: Category | B9: Budget Classification | C9: Estimated Quantity | D9: Estimated Cost per Unit | E9: Estimated Subtotal | F9: 46388 | G9: 46419 | H9: 46447 | I9: 46478 | J9: 46508 | K9: 46539 | L9: 46569 | M9: 46600 | N9: 46631 | O9: 46661 | P9: 46692 | Q9: 46722
A11: Adv & Promotion - Above-The-Line | B11: Main Chart
E12: =SUM(F12:Q12) -> 0 | F12: =F13+F21 -> 0 | G12: =G13+G21 -> 0 | H12: =H13+H21 -> 0 | I12: =I13+I21 -> 0 | J12: =J13+J21 -> 0 | K12: =K13+K21 -> 0 | L12: =L13+L21 -> 0 | M12: =M13+M21 -> 0 | ... Q12: =Q13+Q21 -> 0
A13: Production: | B13: Sub Chart | E13: =SUM(F13:Q13) -> 0 | F13: =SUM(F14:F20) -> 0 | G13: =SUM(G14:G20) -> 0 | H13: =SUM(H14:H20) -> 0 | I13: =SUM(I14:I20) -> 0 | J13: =SUM(J14:J20) -> 0 | K13: =SUM(K14:K20) -> 0 | L13: =SUM(L14:L20) -> 0 | M13: =SUM(M14:M20) -> 0 | ... Q13: =SUM(Q14:Q20) -> 0
A14: TV Commercial | B14: Media Digital, Online, TV, Radio | E14: =SUM(F14:Q14) -> 0
A15: Print Ad | B15: Media Cetak, Brosur, Spanduk, Katalog | E15: =SUM(F15:Q15) -> 0
A16: Radio Ad/spot/jingle | B16: Media Cetak, Brosur, Spanduk, Katalog | E16: =SUM(F16:Q16) -> 0
A17: Website | B17: Media Digital, Online, TV, Radio | E17: =SUM(F17:Q17) -> 0
A18: Other (social media) | B18: Media Digital, Online, TV, Radio | E18: =SUM(F18:Q18) -> 0
E19: =SUM(F19:Q19) -> 0
E20: =SUM(F20:Q20) -> 0
A21: Placement: | B21: Sub Chart | E21: =SUM(F21:Q21) -> 0 | F21: =F22+F27+F32+F37+F41 -> 0 | G21: =G22+G27+G32+G37+G41 -> 0 | H21: =H22+H27+H32+H37+H41 -> 0 | I21: =I22+I27+I32+I37+I41 -> 0 | J21: =J22+J27+J32+J37+J41 -> 0 | K21: =K22+K27+K32+K37+K41 -> 0 | L21: =L22+L27+L32+L37+L41 -> 0 | M21: =M22+M27+M32+M37+M41 -> 0 | ... Q21: =Q22+Q27+Q32+Q37+Q41 -> 0
A22: TV Commercial | E22: =SUM(F22:Q22) -> 0 | F22: =SUM(F23:F26) -> 0 | G22: =SUM(G23:G26) -> 0 | H22: =SUM(H23:H26) -> 0 | I22: =SUM(I23:I26) -> 0 | J22: =SUM(J23:J26) -> 0 | K22: =SUM(K23:K26) -> 0 | L22: =SUM(L23:L26) -> 0 | M22: =SUM(M23:M26) -> 0 | ... Q22: =SUM(Q23:Q26) -> 0
A23: - Spot, sponsor, bumper | B23: Media Digital, Online, TV, Radio | E23: =SUM(F23:Q23) -> 0
A24: - Filler, blocking, TV program | B24: Media Digital, Online, TV, Radio | E24: =SUM(F24:Q24) -> 0
E25: =SUM(F25:Q25) -> 0
E26: =SUM(F26:Q26) -> 0
A27: Print Ad | E27: =SUM(F27:Q27) -> 0 | F27: =SUM(F28:F31) -> 0 | G27: =SUM(G28:G31) -> 0 | H27: =SUM(H28:H31) -> 0 | I27: =SUM(I28:I31) -> 0 | J27: =SUM(J28:J31) -> 0 | K27: =SUM(K28:K31) -> 0 | L27: =SUM(L28:L31) -> 0 | M27: =SUM(M28:M31) -> 0 | ... Q27: =SUM(Q28:Q31) -> 0
A28: - Newspaper & tabloid (national, local, area) | B28: Media Digital, Online, TV, Radio | E28: =SUM(F28:Q28) -> 0
A29: - Magazine (national, local, area) | B29: Media Digital, Online, TV, Radio | E29: =SUM(F29:Q29) -> 0
E30: =SUM(F30:Q30) -> 0
E31: =SUM(F31:Q31) -> 0
A32: Radio Ad | E32: =SUM(F32:Q32) -> 0 | F32: =SUM(F33:F36) -> 0 | G32: =SUM(G33:G36) -> 0 | H32: =SUM(H33:H36) -> 0 | I32: =SUM(I33:I36) -> 0 | J32: =SUM(J33:J36) -> 0 | K32: =SUM(K33:K36) -> 0 | L32: =SUM(L33:L36) -> 0 | M32: =SUM(M33:M36) -> 0 | ... Q32: =SUM(Q33:Q36) -> 0
A33: - Spot & adlibs | B33: Media Digital, Online, TV, Radio | E33: =SUM(F33:Q33) -> 0
A34: - Program, blocking, interview/talkshow | B34: Media Digital, Online, TV, Radio | E34: =SUM(F34:Q34) -> 0 | G34: 0 | H34: 0 | I34: 0 | J34: 0 | K34: 0 | L34: 0 | M34: 0 | O34: 0 | P34: 0 | Q34: 0
E35: =SUM(F35:Q35) -> 0
E36: =SUM(F36:Q36) -> 0
A37: Website | E37: =SUM(F37:Q37) -> 0 | F37: =SUM(F38:F40) -> 0 | G37: =SUM(G38:G40) -> 0 | H37: =SUM(H38:H40) -> 0 | I37: =SUM(I38:I40) -> 0 | J37: =SUM(J38:J40) -> 0 | K37: =SUM(K38:K40) -> 0 | L37: =SUM(L38:L40) -> 0 | M37: =SUM(M38:M40) -> 0 | ... Q37: =SUM(Q38:Q40) -> 0
A38: - Hosting fee, maintenance | B38: Media Digital, Online, TV, Radio | E38: =SUM(F38:Q38) -> 0
E39: =SUM(F39:Q39) -> 0
E40: =SUM(F40:Q40) -> 0
A41: SOCIAL MEDIA | E41: =SUM(F41:Q41) -> 0 | F41: =SUM(F42:F44) -> 0 | G41: =SUM(G42:G44) -> 0 | H41: =SUM(H42:H44) -> 0 | I41: =SUM(I42:I44) -> 0 | J41: =SUM(J42:J44) -> 0 | K41: =SUM(K42:K44) -> 0 | L41: =SUM(L42:L44) -> 0 | M41: =SUM(M42:M44) -> 0 | ... Q41: =SUM(Q42:Q44) -> 0
A42: - Airing cost, blasting cost | B42: Media Digital, Online, TV, Radio | E42: =SUM(F42:Q42) -> 0
E43: =SUM(F43:Q43) -> 0
...

Sheet Budget Employee
B2: EMPLOYEE
B3: ENTITAS: | C3: PT Perintis Triniti Properti Tbk
B4: PROJECT | C4: Head Office
B5: BUDGET YEARS | C5: 2026
C7: 46023 | D7: 46054 | E7: 46082 | F7: 46113 | G7: 46143 | H7: 46174 | I7: 46204 | J7: 46235 | K7: 46266 | L7: 46296 | M7: 46327 | N7: 46357 | O7: TOTAL
B8: Salary | O8: =SUM(C8:N8) -> 0 | P8: Gaji Terakhir
B10: TAX | O10: =SUM(C10:N10) -> 0 | P10: Pajak Terakhir
B11: BPJS | O11: =SUM(C11:N11) -> 0 | P11: BPJS TK 16jt, Kes 2,1jt (terakhir)
O12: =SUM(C12:N12) -> 0
B13: Total Cost | C13: =SUM(C8:C12) -> 0 | D13: =SUM(D8:D12) -> 0 | E13: =SUM(E8:E12) -> 0 | F13: =SUM(F8:F12) -> 0 | G13: =SUM(G8:G12) -> 0 | H13: =SUM(H8:H12) -> 0 | I13: =SUM(I8:I12) -> 0 | J13: =SUM(J8:J12) -> 0 | ... O13: =SUM(O8:O12) -> 0
A17: 1 | C17: YTD JAN | D17: YTD FEB | E17: YTD MAR | F17: YTD APR | G17: YTD MAY | H17: YTD JUN | I17: YTD JUL | J17: YTD AUG | K17: YTD SEP | L17: YTD OCT | M17: YTD NOV | N17: YTD DEC
A18: =A17+1 -> 2 | B18: TOTAL | C18: =SUM($C$13:C13) -> 0 | D18: =SUM($C$13:D13) -> 0 | E18: =SUM($C$13:E13) -> 0 | F18: =SUM($C$13:F13) -> 0 | G18: =SUM($C$13:G13) -> 0 | H18: =SUM($C$13:H13) -> 0 | I18: =SUM($C$13:I13) -> 0 | J18: =SUM($C$13:J13) -> 0 | ... N18: =SUM($C$13:N13) -> 0
C20: =SUM(C18:C19) -> 0 | D20: =SUM(D18:D19) -> 0 | E20: =SUM(E18:E19) -> 0 | F20: =SUM(F18:F19) -> 0 | G20: =SUM(G18:G19) -> 0 | H20: =SUM(H18:H19) -> 0 | I20: =SUM(I18:I19) -> 0 | J20: =SUM(J18:J19) -> 0 | ... N20: =SUM(N18:N19) -> 0

Sheet Dev&Land Budget Plan Cost
D1: DEVELOPMENT BUDGET PLANNING
D2: ENTITAS: | E2: Pilih Perusahaan
D3: PROJECT | E3: Pilih Project
D4: BUDGET YEARS | E4: 2027
B6: A. | C6: DEVELOPMENT COST | E6: SQM | F6: Cost / sqm | G6: Total Nilai RAB / SPK | H6: Total Nilai Realisasi s.d 31 July 2026 | I6: Best Estrimate ( Aug - Des 2026 ) | J6: % Realisasi | L6: Total Nilai Budget 2027 | M6: 46388 | N6: 46419 | O6: 46447 | P6: 46478 | Q6: 46508 | R6: 46539 | S6: 46569 | T6: 46600 | U6: 46631 | V6: 46661 | W6: 46692 | X6: 46722 | Y6: H1 | Z6: H2 | AA6: TOTAL | AB6: H1 | AC6: H2 | AD6: TOTAL
B7: 1 | C7: Land Cost | L7: =SUM(L8,L11) -> 0 | M7: =SUM(M8,M11) -> 0 | N7: =SUM(N8,N11) -> 0 | O7: =SUM(O8,O11) -> 0 | P7: =SUM(P8,P11) -> 0 | Q7: =SUM(Q8,Q11) -> 0 | R7: =SUM(R8,R11) -> 0 | S7: =SUM(S8,S11) -> 0 | ... X7: =SUM(X8,X11) -> 0
C8: 1.1 | D8: Land Improvement Cost | L8: =SUM(M8:X8) -> 0 | M8: =SUM(M9:M10) -> 0 | N8: =SUM(N9:N10) -> 0 | O8: =SUM(O9:O10) -> 0 | P8: =SUM(P9:P10) -> 0 | Q8: =SUM(Q9:Q10) -> 0 | R8: =SUM(R9:R10) -> 0 | S8: =SUM(S9:S10) -> 0 | T8: =SUM(T9:T10) -> 0 | ... X8: =SUM(X9:X10) -> 0
D9: a | J9: =IFERROR((H9+I9)/G9,0) -> 0 | L9: =SUM(M9:X9) -> 0
D10: b | J10: =IFERROR((H10+I10)/G10,0) -> 0 | L10: =SUM(M10:X10) -> 0
C11: 1.2 | D11: Land Acquisition Cost | L11: =SUM(M11:X11) -> 0 | M11: =SUM(M12:M13) -> 0 | N11: =SUM(N12:N13) -> 0 | O11: =SUM(O12:O13) -> 0 | P11: =SUM(P12:P13) -> 0 | Q11: =SUM(Q12:Q13) -> 0 | R11: =SUM(R12:R13) -> 0 | S11: =SUM(S12:S13) -> 0 | T11: =SUM(T12:T13) -> 0 | ... X11: =SUM(X12:X13) -> 0
D12: a | J12: =IFERROR((H12+I12)/G12,0) -> 0 | L12: =SUM(M12:X12) -> 0
D13: b | J13: =IFERROR((H13+I13)/G13,0) -> 0 | L13: =SUM(M13:X13) -> 0
B15: 2 | C15: Development Cost | L15: =SUM(M15:X15) -> 0 | M15: =SUM(M16,M46) -> 0 | N15: =SUM(N16,N46) -> 0 | O15: =SUM(O16,O46) -> 0 | P15: =SUM(P16,P46) -> 0 | Q15: =SUM(Q16,Q46) -> 0 | R15: =SUM(R16,R46) -> 0 | S15: =SUM(S16,S46) -> 0 | T15: =SUM(T16,T46) -> 0 | ... X15: =SUM(X16,X46) -> 0
C16: Hard Cost | L16: =SUM(M16:X16) -> 0 | M16: =SUM(M17,M21,M25,M29,M33,M37,M41) -> 0 | N16: =SUM(N17,N21,N25,N29,N33,N37,N41) -> 0 | O16: =SUM(O17,O21,O25,O29,O33,O37,O41) -> 0 | P16: =SUM(P17,P21,P25,P29,P33,P37,P41) -> 0 | Q16: =SUM(Q17,Q21,Q25,Q29,Q33,Q37,Q41) -> 0 | R16: =SUM(R17,R21,R25,R29,R33,R37,R41) -> 0 | S16: =SUM(S17,S21,S25,S29,S33,S37,S41) -> 0 | T16: =SUM(T17,T21,T25,T29,T33,T37,T41) -> 0 | ... X16: =SUM(X17,X21,X25,X29,X33,X37,X41) -> 0
C17: 2.1 | D17: Preliminaries | L17: =SUM(M17:X17) -> 0 | M17: =SUM(M18:M20) -> 0 | N17: =SUM(N18:N20) -> 0 | O17: =SUM(O18:O20) -> 0 | P17: =SUM(P18:P20) -> 0 | Q17: =SUM(Q18:Q20) -> 0 | R17: =SUM(R18:R20) -> 0 | S17: =SUM(S18:S20) -> 0 | T17: =SUM(T18:T20) -> 0 | ... X17: =SUM(X18:X20) -> 0
D18: a | J18: =IFERROR((H18+I18)/G18,0) -> 0 | L18: =SUM(M18:X18) -> 0
D19: b | J19: =IFERROR((H19+I19)/G19,0) -> 0 | L19: =SUM(M19:X19) -> 0
D20: c | L20: =SUM(M20:X20) -> 0
C21: 2.2 | D21: Pre-Construction | L21: =SUM(M21:X21) -> 0 | M21: =SUM(M22:M24) -> 0 | N21: =SUM(N22:N24) -> 0 | O21: =SUM(O22:O24) -> 0 | P21: =SUM(P22:P24) -> 0 | Q21: =SUM(Q22:Q24) -> 0 | R21: =SUM(R22:R24) -> 0 | S21: =SUM(S22:S24) -> 0 | T21: =SUM(T22:T24) -> 0 | ... X21: =SUM(X22:X24) -> 0
D22: a | J22: =IFERROR((H22+I22)/G22,0) -> 0 | L22: =SUM(M22:X22) -> 0
D23: b | J23: =IFERROR((H23+I23)/G23,0) -> 0 | L23: =SUM(M23:X23) -> 0
D24: c | L24: =SUM(M24:X24) -> 0
C25: 2.3 | D25: Building Construction Cost | L25: =SUM(M25:X25) -> 0 | M25: =SUM(M26:M28) -> 0 | N25: =SUM(N26:N28) -> 0 | O25: =SUM(O26:O28) -> 0 | P25: =SUM(P26:P28) -> 0 | Q25: =SUM(Q26:Q28) -> 0 | R25: =SUM(R26:R28) -> 0 | S25: =SUM(S26:S28) -> 0 | T25: =SUM(T26:T28) -> 0 | ... X25: =SUM(X26:X28) -> 0
D26: a | J26: =IFERROR((H26+I26)/G26,0) -> 0 | L26: =SUM(M26:X26) -> 0
D27: b | J27: =IFERROR((H27+I27)/G27,0) -> 0 | L27: =SUM(M27:X27) -> 0
D28: c | L28: =SUM(M28:X28) -> 0
C29: 2.4 | D29: Parking Construction Cost | L29: =SUM(M29:X29) -> 0 | M29: =SUM(M30:M32) -> 0 | N29: =SUM(N30:N32) -> 0 | O29: =SUM(O30:O32) -> 0 | P29: =SUM(P30:P32) -> 0 | Q29: =SUM(Q30:Q32) -> 0 | R29: =SUM(R30:R32) -> 0 | S29: =SUM(S30:S32) -> 0 | T29: =SUM(T30:T32) -> 0 | ... X29: =SUM(X30:X32) -> 0
D30: a | J30: =IFERROR((H30+I30)/G30,0) -> 0 | L30: =SUM(M30:X30) -> 0
D31: b | J31: =IFERROR((H31+I31)/G31,0) -> 0 | L31: =SUM(M31:X31) -> 0
D32: c | L32: =SUM(M32:X32) -> 0
C33: 2.5 | D33: Infrastructure Cost | L33: =SUM(M33:X33) -> 0 | M33: =SUM(M34:M36) -> 0 | N33: =SUM(N34:N36) -> 0 | O33: =SUM(O34:O36) -> 0 | P33: =SUM(P34:P36) -> 0 | Q33: =SUM(Q34:Q36) -> 0 | R33: =SUM(R34:R36) -> 0 | S33: =SUM(S34:S36) -> 0 | T33: =SUM(T34:T36) -> 0 | ... X33: =SUM(X34:X36) -> 0
D34: a | J34: =IFERROR((H34+I34)/G34,0) -> 0 | L34: =SUM(M34:X34) -> 0
D35: b | J35: =IFERROR((H35+I35)/G35,0) -> 0 | L35: =SUM(M35:X35) -> 0
D36: c | L36: =SUM(M36:X36) -> 0
C37: 2.6 | D37: Facilities Construction Cost | L37: =SUM(M37:X37) -> 0 | M37: =SUM(M38:M40) -> 0 | N37: =SUM(N38:N40) -> 0 | O37: =SUM(O38:O40) -> 0 | P37: =SUM(P38:P40) -> 0 | Q37: =SUM(Q38:Q40) -> 0 | R37: =SUM(R38:R40) -> 0 | S37: =SUM(S38:S40) -> 0 | T37: =SUM(T38:T40) -> 0 | ... X37: =SUM(X38:X40) -> 0
D38: a | J38: =IFERROR((H38+I38)/G38,0) -> 0 | L38: =SUM(M38:X38) -> 0
D39: b | J39: =IFERROR((H39+I39)/G39,0) -> 0 | L39: =SUM(M39:X39) -> 0
D40: c | L40: =SUM(M40:X40) -> 0
C41: 2.7 | D41: Main Gate Construction Cost | L41: =SUM(M41:X41) -> 0 | M41: =SUM(M42:M44) -> 0 | N41: =SUM(N42:N44) -> 0 | O41: =SUM(O42:O44) -> 0 | P41: =SUM(P42:P44) -> 0 | Q41: =SUM(Q42:Q44) -> 0 | R41: =SUM(R42:R44) -> 0 | S41: =SUM(S42:S44) -> 0 | T41: =SUM(T42:T44) -> 0 | ... X41: =SUM(X42:X44) -> 0
D42: a | J42: =IFERROR((H42+I42)/G42,0) -> 0 | L42: =SUM(M42:X42) -> 0
...

Sheet Budget G&A
A1: BUDGET G&A Expenses
A2: ENTITAS: | B2: Pilih Perusahaan
A3: PROJECT | B3: Pilih Project
A4: Division
A5: BUDGET YEARS | B5: 2027
A7: No Akun | B7: Keterangan Biaya | C7: Rincian Budget | D7: Budget Tahun 2027 | E7: 46388 | F7: 46419 | G7: 46447 | H7: 46478 | I7: 46508 | J7: 46539 | K7: 46569 | L7: 46600 | M7: 46631 | N7: 46661 | O7: 46692 | P7: 46722
A8: 62210001 | B8: BEBAN PEMELIHARAAN & RENOVASI BANGUNAN KANTOR | D8: =SUM(E8:P8) -> 0
A9: 62210002 | B9: BEBAN PEMELIHARAAN INVENTARIS KANTOR | D9: =SUM(E9:P9) -> 0
A10: 62210003 | B10: BEBAN PEMELIHARAAN KENDARAAN KANTOR | D10: =SUM(E10:P10) -> 0
A11: 62220001 | B11: BEBAN SEWA BANGUNAN UNTUK OPERASIONAL KANTOR | D11: =SUM(E11:P11) -> 0
A12: 62220002 | B12: BEBAN SEWA RUMAH MESS UNTUK OPERASIONAL | D12: =SUM(E12:P12) -> 0
A13: 62220003 | B13: BEBAN SEWA GEDUNG UNTUK ACARA KANTOR | D13: =SUM(E13:P13) -> 0
A14: 62220004 | B14: BEBAN SEWA KENDARAAN | D14: =SUM(E14:P14) -> 0
A15: 62220005 | B15: BEBAN SEWA LAINNYA | D15: =SUM(E15:P15) -> 0
A16: 62220006 | B16: BEBAN SEWA PERALATAN | D16: =SUM(E16:P16) -> 0
A17: 62220007 | B17: BEBAN SEWA RUMAH DINAS / MESS KARYAWAN | D17: =SUM(E17:P17) -> 0
A18: 62220008 | B18: BEBAN SEWA PERALATAN KANTOR | D18: =SUM(E18:P18) -> 0
A19: 62230001 | B19: BEBAN ASURANSI BANGUNAN KANTOR | D19: =SUM(E19:P19) -> 0
... A62: 62280016 | B62: BEBAN KANTOR HAND OVER | D62: =SUM(E62:P62) -> 0
D63: =SUM(D8:D62) -> 0 | E63: =SUM(E8:E62) -> 0 | F63: =SUM(F8:F62) -> 0 | G63: =SUM(G8:G62) -> 0 | H63: =SUM(H8:H62) -> 0 | I63: =SUM(I8:I62) -> 0 | J63: =SUM(J8:J62) -> 0 | K63: =SUM(K8:K62) -> 0 | ... P63: =SUM(P8:P62) -> 0
C67: TOTAL | E67: YTD JAN | F67: YTD FEB | G67: YTD MAR | H67: YTD APR | I67: YTD MAY | J67: YTD JUN | K67: YTD JUL | L67: YTD AUG | M67: YTD SEP | N67: YTD OCT | O67: YTD NOV | P67: YTD DEC
E68: =SUM(E63) -> 0 | F68: =SUM($E$63:F$63) -> 0 | G68: =SUM($E$63:G$63) -> 0 | H68: =SUM($E$63:H$63) -> 0 | I68: =SUM($E$63:I$63) -> 0 | J68: =SUM($E$63:J$63) -> 0 | K68: =SUM($E$63:K$63) -> 0 | L68: =SUM($E$63:L$63) -> 0 | M68: =SUM($E$63:M$63) -> 0 | ... P68: =SUM($E$63:P$63) -> 0

Sheet Budget Others
A1: BUDGET Others
A2: ENTITAS: | B2: Pilih Perusahaan
A3: PROJECT | B3: Pilih Project
A4: Division
A5: BUDGET YEARS | B5: 2027
A7: No Akun | B7: Keterangan Biaya | C7: Rincian Budget | D7: Budget Tahun 2027 | E7: 46388 | F7: 46419 | G7: 46447 | H7: 46478 | I7: 46508 | J7: 46539 | K7: 46569 | L7: 46600 | M7: 46631 | N7: 46661 | O7: 46692 | P7: 46722
A8: 71110001 | B8: PENDAPATAN BUNGA | D8: =SUM(E8:P8) -> 0
A9: 71110002 | B9: PENDAPATAN BUNGA DEPOSITO | D9: =SUM(E9:P9) -> 0
A10: 71110003 | B10: PENDAPATAN BUNGA JASA GIRO | D10: =SUM(E10:P10) -> 0
A11: 71110004 | B11: PENDAPATAN BUNGA OBLIGASI | D11: =SUM(E11:P11) -> 0
A12: 71120001 | B12: PENDAPATAN DENDA PENJUALAN | D12: =SUM(E12:P12) -> 0
A13: 71120002 | B13: PENDAPATAN JASA GIRO | D13: =SUM(E13:P13) -> 0
A14: 71120003 | B14: PENDAPATAN ADMINISTRASI PENJUALAN | D14: =SUM(E14:P14) -> 0
A15: 71120004 | B15: PENDAPATAN ATAS PENJUALAN ASET TETAP | D15: =SUM(E15:P15) -> 0
A16: 71120005 | B16: PENDAPATAN INSENTIF KPA | D16: =SUM(E16:P16) -> 0
A17: 71120006 | B17: PENDAPATAN KOMPREHENSIF LAIN - PASKA KERJA | D17: =SUM(E17:P17) -> 0
A18: 71120007 | B18: PENDAPATAN LAIN-LAIN | D18: =SUM(E18:P18) -> 0
A19: 71120008 | B19: REIMBURSMENT (BILLING RATE) | D19: =SUM(E19:P19) -> 0
... A46: 72120018 | B46: BEBAN KOMPREHENSIF LAIN - PASKA KERJA | D46: =SUM(E46:P46) -> 0
E47: =SUM(E8:E46) -> 0 | F47: =SUM(F8:F46) -> 0 | G47: =SUM(G8:G46) -> 0 | H47: =SUM(H8:H46) -> 0 | I47: =SUM(I8:I46) -> 0 | J47: =SUM(J8:J46) -> 0 | K47: =SUM(K8:K46) -> 0 | L47: =SUM(L8:L46) -> 0 | ... P47: =SUM(P8:P46) -> 0
E48: YTD JAN | F48: YTD FEB | G48: YTD MAR | H48: YTD APR | I48: YTD MAY | J48: YTD JUN | K48: YTD JUL | L48: YTD AUG | M48: YTD SEP | N48: YTD OCT | O48: YTD NOV | P48: YTD DEC
E49: =SUM(E47) -> 0 | F49: =SUM($E$47:F$47) -> 0 | G49: =SUM($E$47:G$47) -> 0 | H49: =SUM($E$47:H$47) -> 0 | I49: =SUM($E$47:I$47) -> 0 | J49: =SUM($E$47:J$47) -> 0 | K49: =SUM($E$47:K$47) -> 0 | L49: =SUM($E$47:L$47) -> 0 | M49: =SUM($E$47:M$47) -> 0 | ... P49: =SUM($E$47:P$47) -> 0

Sheet Budget Finance Expenses
A1: BUDGET Finance expense
A2: ENTITAS: | B2: Pilih Perusahaan
A3: PROJECT | B3: Pilih Project
A4: Division
A5: BUDGET YEARS | B5: 2027
A7: No Akun | B7: Keterangan Biaya | C7: Rincian Budget | D7: Budget Tahun 2027 | E7: 46388 | F7: 46419 | G7: 46447 | H7: 46478 | I7: 46508 | J7: 46539 | K7: 46569 | L7: 46600 | M7: 46631 | N7: 46661 | O7: 46692 | P7: 46722
A8: 72110001 | B8: BEBAN BUNGA PINJAMAN | D8: =SUM(E8:P8) -> 0
A9: 72110002 | B9: BEBAN PROVISI DAN ADM PINJAMAN | D9: =SUM(E9:P9) -> 0
A10: 72110003 | B10: BEBAN ASURANSI ATAS PINJAMAN | D10: =SUM(E10:P10) -> 0
A11: 72110004 | B11: BEBAN LINDUNG NILAI ATAS PINJAMAN | D11: =SUM(E11:P11) -> 0
A12: 72120007 | B12: BIAYA BUNGA, PROVISI & ADM PINJAMAN | D12: =SUM(E12:P12) -> 0
A13: 72120015 | B13: PAJAK BUNGA DEPOSITO | D13: =SUM(E13:P13) -> 0
A14: 72120019 | B14: BEBAN LAIN-LAIN | D14: =SUM(E14:P14) -> 0
A15: 72120020 | B15: BEBAN BUNGA UANG MUKA PELANGGAN | D15: =SUM(E15:P15) -> 0
A16: 11610010 | B16: UANG MUKA PROYEK | D16: =SUM(E16:P16) -> 0
A17: TOTAL | D17: =SUM(D8:D16) -> 0 | E17: =SUM(E8:E16) -> 0 | F17: =SUM(F8:F16) -> 0 | G17: =SUM(G8:G16) -> 0 | H17: =SUM(H8:H16) -> 0 | I17: =SUM(I8:I16) -> 0 | J17: =SUM(J8:J16) -> 0 | K17: =SUM(K8:K16) -> 0 | ... P17: =SUM(P8:P16) -> 0
E19: YTD JAN | F19: YTD FEB | G19: YTD MAR | H19: YTD APR | I19: YTD MAY | J19: YTD JUN | K19: YTD JUL | L19: YTD AUG | M19: YTD SEP | N19: YTD OCT | O19: YTD NOV | P19: YTD DEC
C20: TOTAL | E20: =SUM(E17) -> 0 | F20: =SUM($E$17:F$17) -> 0 | G20: =SUM($E$17:G$17) -> 0 | H20: =SUM($E$17:H$17) -> 0 | I20: =SUM($E$17:I$17) -> 0 | J20: =SUM($E$17:J$17) -> 0 | K20: =SUM($E$17:K$17) -> 0 | L20: =SUM($E$17:L$17) -> 0 | M20: =SUM($E$17:M$17) -> 0 | ... P20: =SUM($E$17:P$17) -> 0

Sheet Budget Corp Event Exihibition
A1: CORPORATE EVENT & EXHIBITION PLANNING
A2: ENTITAS: | B2: Pilih Perusahaan
A3: PROJECT: | B3: Pilih Project
A4: DIVISION: | G4: Corsec / Investor & Public Relation / HC Even/ Training & Development
A5: BUDGET YEAR: | B5: 2027
A7: =B4&" "&"Budget Plan" -> Budget Plan | F7: 2027
A8: Activitiy | B8: Classification | C8: Estimated Quantity | D8: Estimated Cost per Unit | E8: Estimated Subtotal | F8: 46388 | G8: 46419 | H8: 46447 | I8: 46478 | J8: 46508 | K8: 46539 | L8: 46569 | M8: 46600 | N8: 46631 | O8: 46661 | P8: 46692 | Q8: 46722
E11: =SUM(F11:Q11) -> 0 | F11: =SUM(F12:F17) -> 0 | G11: =SUM(G12:G17) -> 0 | H11: =SUM(H12:H17) -> 0 | I11: =SUM(I12:I17) -> 0 | J11: =SUM(J12:J17) -> 0 | K11: =SUM(K12:K17) -> 0 | L11: =SUM(L12:L17) -> 0 | M11: =SUM(M12:M17) -> 0 | ... Q11: =SUM(Q12:Q17) -> 0
E12: =C12*D12 -> 0
E13: =C13*D13 -> 0
E14: =C14*D14 -> 0
E15: =C15*D15 -> 0
E16: =C16*D16 -> 0
E17: =C17*D17 -> 0
E18: =SUM(F18:Q18) -> 0
E19: =SUM(F19:Q19) -> 0 | F19: =SUM(F20:F22) -> 0 | G19: =SUM(G20:G22) -> 0 | H19: =SUM(H20:H22) -> 0 | I19: =SUM(I20:I22) -> 0 | J19: =SUM(J20:J22) -> 0 | K19: =SUM(K20:K22) -> 0 | L19: =SUM(L20:L22) -> 0 | M19: =SUM(M20:M22) -> 0 | ... Q19: =SUM(Q20:Q22) -> 0
E20: =C20*D20 -> 0 | K20: =E20 -> 0
E21: =C21*D21 -> 0 | J21: =E21 -> 0
E22: =C22*D22 -> 0
E23: =SUM(F23:Q23) -> 0
E24: =SUM(F24:Q24) -> 0 | F24: =SUM(F25:F27) -> 0 | G24: =SUM(G25:G27) -> 0 | H24: =SUM(H25:H27) -> 0 | I24: =SUM(I25:I27) -> 0 | J24: =SUM(J25:J27) -> 0 | K24: =SUM(K25:K27) -> 0 | L24: =SUM(L25:L27) -> 0 | M24: =SUM(M25:M27) -> 0 | ... Q24: =SUM(Q25:Q27) -> 0
E25: =SUM(F25:Q25) -> 0
E26: =SUM(F26:Q26) -> 0
E27: =SUM(F27:Q27) -> 0
A30: =B4&" "&"Budget Plan" -> Budget Plan | E30: =SUM(F30:Q30) -> 0 | F30: =F24+F19+F11 -> 0 | G30: =G24+G19+G11 -> 0 | H30: =H24+H19+H11 -> 0 | I30: =I24+I19+I11 -> 0 | J30: =J24+J19+J11 -> 0 | K30: =K24+K19+K11 -> 0 | L30: =L24+L19+L11 -> 0 | M30: =M24+M19+M11 -> 0 | ... Q30: =Q24+Q19+Q11 -> 0
F47: YTD JAN | G47: YTD FEB | H47: YTD MAR | I47: YTD APR | J47: YTD MAY | K47: YTD JUN | L47: YTD JUL | M47: YTD AUG | N47: YTD SEP | O47: YTD OCT | P47: YTD NOV | Q47: YTD DEC
